18:12:11.631 - DEBUG - Received data: {'topic': '/market/level2:SWELL-USDT', 'type': 'message', 'subject': 'trade.l2update', 'data': {'changes': {'asks': [], 'bids': [['0.049115', '1830', '12467575']]}, 'sequenceEnd': 12467575, 'sequenceStart': 12467575, 'symbol': 'SWELL-USDT', 'time': 1731089522110}} - get_price_websocket_level2
18:12:11.631 - INFO - data from WebSocket: {'asks': [], 'bids': [['0.049115', '1830', '12467575']]}  - get_price_websocket_level2
18:12:11.631 - DEBUG - Data from socket: {'asks': [], 'bids': [['0.049115', '1830', '12467575']]} - get_price_websocket_level2
Successfully retrieved SWELL price: {'asks': [], 'bids': [['0.049115', '1830', '12467575']]}
18:13:11.998 - DEBUG - Received data: {'topic': '/market/level2:SWELL-USDT', 'type': 'message', 'subject': 'trade.l2update', 'data': {'changes': {'asks': [], 'bids': [['0.009001', '258447', '12479014']]}, 'sequenceEnd': 12479014, 'sequenceStart': 12479014, 'symbol': 'SWELL-USDT', 'time': 1731089582464}} - get_price_websocket_level2
18:13:11.998 - INFO - data from WebSocket: {'asks': [], 'bids': [['0.009001', '258447', '12479014']]}  - get_price_websocket_level2
18:13:11.998 - DEBUG - Data from socket: {'asks': [], 'bids': [['0.009001', '258447', '12479014']]} - get_price_websocket_level2
Successfully retrieved SWELL price: {'asks': [], 'bids': [['0.009001', '258447', '12479014']]}
18:14:11.354 - DEBUG - Received data: {'topic': '/market/level2:SWELL-USDT', 'type': 'message', 'subject': 'trade.l2update', 'data': {'changes': {'asks': [], 'bids': [['0.009041', '110273', '12487876']]}, 'sequenceEnd': 12487876, 'sequenceStart': 12487876, 'symbol': 'SWELL-USDT', 'time': 1731089641845}} - get_price_websocket_level2
18:14:11.354 - INFO - data from WebSocket: {'asks': [], 'bids': [['0.009041', '110273', '12487876']]}  - get_price_websocket_level2
18:14:11.354 - DEBUG - Data from socket: {'asks': [], 'bids': [['0.009041', '110273', '12487876']]} - get_price_websocket_level2
Successfully retrieved SWELL price: {'asks': [], 'bids': [['0.009041', '110273', '12487876']]}
18:15:11.699 - DEBUG - Received data: {'topic': '/market/level2:SWELL-USDT', 'type': 'message', 'subject': 'trade.l2update', 'data': {'changes': {'asks': [], 'bids': [['0.048434', '2920', '12498900']]}, 'sequenceEnd': 12498900, 'sequenceStart': 12498900, 'symbol': 'SWELL-USDT', 'time': 1731089702405}} - get_price_websocket_level2
18:15:11.699 - INFO - data from WebSocket: {'asks': [], 'bids': [['0.048434', '2920', '12498900']]}  - get_price_websocket_level2
18:15:11.699 - DEBUG - Data from socket: {'asks': [], 'bids': [['0.048434', '2920', '12498900']]} - get_price_websocket_level2
Successfully retrieved SWELL price: {'asks': [], 'bids': [['0.048434', '2920', '12498900']]}
18:16:12.083 - DEBUG - Received data: {'topic': '/market/level2:SWELL-USDT', 'type': 'message', 'subject': 'trade.l2update', 'data': {'changes': {'asks': [['0.049816', '2048', '12509814']], 'bids': []}, 'sequenceEnd': 12509814, 'sequenceStart': 12509814, 'symbol': 'SWELL-USDT', 'time': 1731089762571}} - get_price_websocket_level2
18:16:12.083 - INFO - data from WebSocket: {'asks': [['0.049816', '2048', '12509814']], 'bids': []}  - get_price_websocket_level2
18:16:12.084 - DEBUG - Data from socket: {'asks': [['0.049816', '2048', '12509814']], 'bids': []} - get_price_websocket_level2
Successfully retrieved SWELL price: {'asks': [['0.049816', '2048', '12509814']], 'bids': []}
18:17:11.422 - DEBUG - Received data: {'topic': '/market/level2:SWELL-USDT', 'type': 'message', 'subject': 'trade.l2update', 'data': {'changes': {'asks': [], 'bids': [['0.048391', '0', '12520838']]}, 'sequenceEnd': 12520838, 'sequenceStart': 12520838, 'symbol': 'SWELL-USDT', 'time': 1731089822115}} - get_price_websocket_level2
18:17:11.422 - INFO - data from WebSocket: {'asks': [], 'bids': [['0.048391', '0', '12520838']]}  - get_price_websocket_level2
18:17:11.422 - DEBUG - Data from socket: {'asks': [], 'bids': [['0.048391', '0', '12520838']]} - get_price_websocket_level2
Successfully retrieved SWELL price: {'asks': [], 'bids': [['0.048391', '0', '12520838']]}
18:18:11.995 - DEBUG - Received data: {'topic': '/market/level2:SWELL-USDT', 'type': 'message', 'subject': 'trade.l2update', 'data': {'changes': {'asks': [], 'bids': [['0.049143', '0', '12530275']]}, 'sequenceEnd': 12530275, 'sequenceStart': 12530275, 'symbol': 'SWELL-USDT', 'time': 1731089882447}} - get_price_websocket_level2
18:18:11.995 - INFO - data from WebSocket: {'asks': [], 'bids': [['0.049143', '0', '12530275']]}  - get_price_websocket_level2
18:18:11.996 - DEBUG - Data from socket: {'asks': [], 'bids': [['0.049143', '0', '12530275']]} - get_price_websocket_level2
Successfully retrieved SWELL price: {'asks': [], 'bids': [['0.049143', '0', '12530275']]}
18:36:42.016 - DEBUG - Received data: {'topic': '/market/level2:SWELL-USDT', 'type': 'message', 'subject': 'trade.l2update', 'data': {'changes': {'asks': [], 'bids': [['0.049025', '1981', '12673833']]}, 'sequenceEnd': 12673833, 'sequenceStart': 12673833, 'symbol': 'SWELL-USDT', 'time': 1731090902476}} - get_price_websocket_level2
18:36:42.016 - INFO - data from WebSocket: {'asks': [], 'bids': [['0.049025', '1981', '12673833']]}  - get_price_websocket_level2
18:36:42.016 - DEBUG - Data from socket: {'asks': [], 'bids': [['0.049025', '1981', '12673833']]} - get_price_websocket_level2
Successfully retrieved SWELL price: {'asks': [], 'bids': [['0.049025', '1981', '12673833']]}
18:38:41.510 - DEBUG - Received data: {'topic': '/market/level2:SWELL-USDT', 'type': 'message', 'subject': 'trade.l2update', 'data': {'changes': {'asks': [['0.050576', '36400', '12685827']], 'bids': []}, 'sequenceEnd': 12685827, 'sequenceStart': 12685827, 'symbol': 'SWELL-USDT', 'time': 1731091021953}} - get_price_websocket_level2
18:38:41.510 - INFO - data from WebSocket: {'asks': [['0.050576', '36400', '12685827']], 'bids': []}  - get_price_websocket_level2
18:38:41.510 - DEBUG - Data from socket: {'asks': [['0.050576', '36400', '12685827']], 'bids': []} - get_price_websocket_level2
Successfully retrieved SWELL price: {'asks': [['0.050576', '36400', '12685827']], 'bids': []}
18:47:22.040 - DEBUG - Received data: {'topic': '/market/level2:SWELL-USDT', 'type': 'message', 'subject': 'trade.l2update', 'data': {'changes': {'asks': [], 'bids': [['0.049373', '0', '12698296']]}, 'sequenceEnd': 12698296, 'sequenceStart': 12698296, 'symbol': 'SWELL-USDT', 'time': 1731091142487}} - get_price_websocket_level2
18:47:22.040 - INFO - data from WebSocket: {'asks': [], 'bids': [['0.049373', '0', '12698296']]}  - get_price_websocket_level2
18:47:22.040 - DEBUG - Data from socket: {'asks': [], 'bids': [['0.049373', '0', '12698296']]} - get_price_websocket_level2
Successfully retrieved SWELL price: {'asks': [], 'bids': [['0.049373', '0', '12698296']]}
18:54:21.893 - DEBUG - Received data: {'topic': '/market/level2:SWELL-USDT', 'type': 'message', 'subject': 'trade.l2update', 'data': {'changes': {'asks': [], 'bids': [['0.041626', '9434', '12753798']]}, 'sequenceEnd': 12753798, 'sequenceStart': 12753798, 'symbol': 'SWELL-USDT', 'time': 1731091562366}} - get_price_websocket_level2
18:54:21.893 - INFO - data from WebSocket: {'asks': [], 'bids': [['0.041626', '9434', '12753798']]}  - get_price_websocket_level2
18:54:21.893 - DEBUG - Data from socket: {'asks': [], 'bids': [['0.041626', '9434', '12753798']]} - get_price_websocket_level2
Successfully retrieved SWELL price: {'asks': [], 'bids': [['0.041626', '9434', '12753798']]}
18:56:21.302 - DEBUG - Received data: {'topic': '/market/level2:SWELL-USDT', 'type': 'message', 'subject': 'trade.l2update', 'data': {'changes': {'asks': [], 'bids': [['0.047553', '549', '12764862']]}, 'sequenceEnd': 12764862, 'sequenceStart': 12764862, 'symbol': 'SWELL-USDT', 'time': 1731091681795}} - get_price_websocket_level2
18:56:21.302 - INFO - data from WebSocket: {'asks': [], 'bids': [['0.047553', '549', '12764862']]}  - get_price_websocket_level2
18:56:21.302 - DEBUG - Data from socket: {'asks': [], 'bids': [['0.047553', '549', '12764862']]} - get_price_websocket_level2
Successfully retrieved SWELL price: {'asks': [], 'bids': [['0.047553', '549', '12764862']]}
19:08:00.001 - DEBUG - Received data: {'topic': '/market/level2:XRP-USDT', 'type': 'message', 'subject': 'trade.l2update', 'data': {'changes': {'asks': [['0.54998', '707.5314', '4702980911']], 'bids': []}, 'sequenceEnd': 4702980911, 'sequenceStart': 4702980911, 'symbol': 'XRP-USDT', 'time': 1731092761826}} - get_price_websocket_level2
19:08:00.001 - INFO - data from WebSocket: {'asks': [['0.54998', '707.5314', '4702980911']], 'bids': []}  - get_price_websocket_level2
19:08:00.001 - DEBUG - Data from socket: {'asks': [['0.54998', '707.5314', '4702980911']], 'bids': []} - get_price_websocket_level2
19:08:00.001 - INFO - Successfully retrieved XRP price: {'asks': [['0.54998', '707.5314', '4702980911']], 'bids': []} - main
20:00:00.000 - DEBUG - Received data: {'topic': '/market/level2:XRP-USDT', 'type': 'message', 'subject': 'trade.l2update', 'data': {'changes': {'asks': [], 'bids': [['0.5508', '72.6218', '4703112650']]}, 'sequenceEnd': 4703112650, 'sequenceStart': 4703112650, 'symbol': 'XRP-USDT', 'time': 1731094922572}} - get_price_websocket_level2
20:00:00.001 - INFO - data from WebSocket: {'asks': [], 'bids': [['0.5508', '72.6218', '4703112650']]}  - get_price_websocket_level2
20:00:00.001 - DEBUG - Data from socket: {'asks': [], 'bids': [['0.5508', '72.6218', '4703112650']]} - get_price_websocket_level2
20:00:00.001 - INFO - Successfully retrieved XRP price: {'asks': [], 'bids': [['0.5508', '72.6218', '4703112650']]} - main
20:45:00.002 - DEBUG - Received data: {'topic': '/market/level2:XRP-USDT', 'type': 'message', 'subject': 'trade.l2update', 'data': {'changes': {'asks': [], 'bids': [['0.54819', '0', '4703273278']]}, 'sequenceEnd': 4703273278, 'sequenceStart': 4703273278, 'symbol': 'XRP-USDT', 'time': 1731097682340}} - get_price_websocket_level2
20:45:00.002 - INFO - data from WebSocket: {'asks': [], 'bids': [['0.54819', '0', '4703273278']]}  - get_price_websocket_level2
20:45:00.002 - DEBUG - Data from socket: {'asks': [], 'bids': [['0.54819', '0', '4703273278']]} - get_price_websocket_level2
20:45:00.002 - INFO - Successfully retrieved XRP price: {'asks': [], 'bids': [['0.54819', '0', '4703273278']]} - main
21:00:00.001 - DEBUG - Received data: {'topic': '/market/level2:XRP-USDT', 'type': 'message', 'subject': 'trade.l2update', 'data': {'changes': {'asks': [['0.54916', '0', '4703361976']], 'bids': []}, 'sequenceEnd': 4703361976, 'sequenceStart': 4703361976, 'symbol': 'XRP-USDT', 'time': 1731099361930}} - get_price_websocket_level2
21:00:00.001 - INFO - data from WebSocket: {'asks': [['0.54916', '0', '4703361976']], 'bids': []}  - get_price_websocket_level2
21:00:00.001 - DEBUG - Data from socket: {'asks': [['0.54916', '0', '4703361976']], 'bids': []} - get_price_websocket_level2
21:00:00.001 - INFO - Successfully retrieved XRP price: {'asks': [['0.54916', '0', '4703361976']], 'bids': []} - main
21:15:00.002 - DEBUG - Received data: {'topic': '/market/level2:XRP-USDT', 'type': 'message', 'subject': 'trade.l2update', 'data': {'changes': {'asks': [], 'bids': [['0.54852', '1092.2993', '4703372993']]}, 'sequenceEnd': 4703372993, 'sequenceStart': 4703372993, 'symbol': 'XRP-USDT', 'time': 1731099600764}} - get_price_websocket_level2
21:15:00.002 - INFO - data from WebSocket: {'asks': [], 'bids': [['0.54852', '1092.2993', '4703372993']]}  - get_price_websocket_level2
21:15:00.003 - DEBUG - Data from socket: {'asks': [], 'bids': [['0.54852', '1092.2993', '4703372993']]} - get_price_websocket_level2
21:15:00.003 - INFO - Successfully retrieved XRP price: {'asks': [], 'bids': [['0.54852', '1092.2993', '4703372993']]} - main
21:45:00.000 - DEBUG - Received data: {'topic': '/market/level2:XRP-USDT', 'type': 'message', 'subject': 'trade.l2update', 'data': {'changes': {'asks': [], 'bids': [['0.54594', '563.4203', '4703459814']]}, 'sequenceEnd': 4703459814, 'sequenceStart': 4703459814, 'symbol': 'XRP-USDT', 'time': 1731101282869}} - get_price_websocket_level2
21:45:00.000 - INFO - data from WebSocket: {'asks': [], 'bids': [['0.54594', '563.4203', '4703459814']]}  - get_price_websocket_level2
21:45:00.000 - DEBUG - Data from socket: {'asks': [], 'bids': [['0.54594', '563.4203', '4703459814']]} - get_price_websocket_level2
21:45:00.000 - INFO - Successfully retrieved XRP price: {'asks': [], 'bids': [['0.54594', '563.4203', '4703459814']]} - main
22:00:00.000 - DEBUG - Received data: {'topic': '/market/level2:XRP-USDT', 'type': 'message', 'subject': 'trade.l2update', 'data': {'changes': {'asks': [], 'bids': [['0.54726', '0', '4703505322']]}, 'sequenceEnd': 4703505322, 'sequenceStart': 4703505322, 'symbol': 'XRP-USDT', 'time': 1731102300794}} - get_price_websocket_level2
22:00:00.000 - INFO - data from WebSocket: {'asks': [], 'bids': [['0.54726', '0', '4703505322']]}  - get_price_websocket_level2
22:00:00.000 - DEBUG - Data from socket: {'asks': [], 'bids': [['0.54726', '0', '4703505322']]} - get_price_websocket_level2
22:00:00.001 - INFO - Successfully retrieved XRP price: {'asks': [], 'bids': [['0.54726', '0', '4703505322']]} - main
22:15:00.001 - DEBUG - Received data: {'topic': '/market/level2:XRP-USDT', 'type': 'message', 'subject': 'trade.l2update', 'data': {'changes': {'asks': [['0.55231', '1896.3713', '4703555137']], 'bids': []}, 'sequenceEnd': 4703555137, 'sequenceStart': 4703555137, 'symbol': 'XRP-USDT', 'time': 1731103201356}} - get_price_websocket_level2
22:15:00.002 - INFO - data from WebSocket: {'asks': [['0.55231', '1896.3713', '4703555137']], 'bids': []}  - get_price_websocket_level2
22:15:00.002 - DEBUG - Data from socket: {'asks': [['0.55231', '1896.3713', '4703555137']], 'bids': []} - get_price_websocket_level2
22:15:00.002 - INFO - Successfully retrieved XRP price: {'asks': [['0.55231', '1896.3713', '4703555137']], 'bids': []} - main
22:30:00.000 - DEBUG - Received data: {'topic': '/market/level2:XRP-USDT', 'type': 'message', 'subject': 'trade.l2update', 'data': {'changes': {'asks': [], 'bids': [['0.55026', '18.2897', '4703600384']]}, 'sequenceEnd': 4703600384, 'sequenceStart': 4703600384, 'symbol': 'XRP-USDT', 'time': 1731104100794}} - get_price_websocket_level2
22:30:00.000 - INFO - data from WebSocket: {'asks': [], 'bids': [['0.55026', '18.2897', '4703600384']]}  - get_price_websocket_level2
22:30:00.000 - DEBUG - Data from socket: {'asks': [], 'bids': [['0.55026', '18.2897', '4703600384']]} - get_price_websocket_level2
22:30:00.000 - INFO - Successfully retrieved XRP price: {'asks': [], 'bids': [['0.55026', '18.2897', '4703600384']]} - main
07:00:00.001 - DEBUG - Received data: {'topic': '/market/level2:XRP-USDT', 'type': 'message', 'subject': 'trade.l2update', 'data': {'changes': {'asks': [['0.55476', '1090.6182', '4705038407']], 'bids': []}, 'sequenceEnd': 4705038407, 'sequenceStart': 4705038407, 'symbol': 'XRP-USDT', 'time': 1731134521877}} - get_price_websocket_level2
07:00:00.001 - INFO - data from WebSocket: {'asks': [['0.55476', '1090.6182', '4705038407']], 'bids': []}  - get_price_websocket_level2
07:00:00.001 - DEBUG - Data from socket: {'asks': [['0.55476', '1090.6182', '4705038407']], 'bids': []} - get_price_websocket_level2
07:00:00.001 - INFO - Successfully retrieved XRP price: {'asks': [['0.55476', '1090.6182', '4705038407']], 'bids': []} - main
07:30:00.003 - DEBUG - Received data: {'topic': '/market/level2:XRP-USDT', 'type': 'message', 'subject': 'trade.l2update', 'data': {'changes': {'asks': [], 'bids': [['0.55116', '3122.844', '4705167651']]}, 'sequenceEnd': 4705167651, 'sequenceStart': 4705167651, 'symbol': 'XRP-USDT', 'time': 1731137282271}} - get_price_websocket_level2
07:30:00.003 - INFO - data from WebSocket: {'asks': [], 'bids': [['0.55116', '3122.844', '4705167651']]}  - get_price_websocket_level2
07:30:00.003 - DEBUG - Data from socket: {'asks': [], 'bids': [['0.55116', '3122.844', '4705167651']]} - get_price_websocket_level2
07:30:00.004 - INFO - Successfully retrieved XRP price: {'asks': [], 'bids': [['0.55116', '3122.844', '4705167651']]} - main
08:00:00.001 - DEBUG - Received data: {'topic': '/market/level2:XRP-USDT', 'type': 'message', 'subject': 'trade.l2update', 'data': {'changes': {'asks': [], 'bids': [['0.54996', '2167.3127', '4705203838']]}, 'sequenceEnd': 4705203838, 'sequenceStart': 4705203838, 'symbol': 'XRP-USDT', 'time': 1731138122191}} - get_price_websocket_level2
08:00:00.001 - INFO - data from WebSocket: {'asks': [], 'bids': [['0.54996', '2167.3127', '4705203838']]}  - get_price_websocket_level2
08:00:00.001 - DEBUG - Data from socket: {'asks': [], 'bids': [['0.54996', '2167.3127', '4705203838']]} - get_price_websocket_level2
08:00:00.002 - INFO - Successfully retrieved XRP price: {'asks': [], 'bids': [['0.54996', '2167.3127', '4705203838']]} - main
08:15:00.000 - DEBUG - Received data: {'topic': '/market/level2:XRP-USDT', 'type': 'message', 'subject': 'trade.l2update', 'data': {'changes': {'asks': [], 'bids': [['0.5519', '36.2385', '4705256841']]}, 'sequenceEnd': 4705256841, 'sequenceStart': 4705256841, 'symbol': 'XRP-USDT', 'time': 1731139202288}} - get_price_websocket_level2
08:15:00.000 - INFO - data from WebSocket: {'asks': [], 'bids': [['0.5519', '36.2385', '4705256841']]}  - get_price_websocket_level2
08:15:00.000 - DEBUG - Data from socket: {'asks': [], 'bids': [['0.5519', '36.2385', '4705256841']]} - get_price_websocket_level2
08:15:00.000 - INFO - Successfully retrieved XRP price: {'asks': [], 'bids': [['0.5519', '36.2385', '4705256841']]} - main
08:45:00.007 - DEBUG - Received data: {'topic': '/market/level2:XRP-USDT', 'type': 'message', 'subject': 'trade.l2update', 'data': {'changes': {'asks': [['0.55648', '774.8066', '4705336717']], 'bids': []}, 'sequenceEnd': 4705336717, 'sequenceStart': 4705336717, 'symbol': 'XRP-USDT', 'time': 1731140882842}} - get_price_websocket_level2
08:45:00.008 - INFO - data from WebSocket: {'asks': [['0.55648', '774.8066', '4705336717']], 'bids': []}  - get_price_websocket_level2
08:45:00.008 - DEBUG - Data from socket: {'asks': [['0.55648', '774.8066', '4705336717']], 'bids': []} - get_price_websocket_level2
08:45:00.008 - INFO - Successfully retrieved XRP price: {'asks': [['0.55648', '774.8066', '4705336717']], 'bids': []} - main
09:00:00.001 - DEBUG - Received data: {'topic': '/market/level2:XRP-USDT', 'type': 'message', 'subject': 'trade.l2update', 'data': {'changes': {'asks': [['0.55514', '562.9231', '4705448053']], 'bids': []}, 'sequenceEnd': 4705448053, 'sequenceStart': 4705448053, 'symbol': 'XRP-USDT', 'time': 1731142563239}} - get_price_websocket_level2
09:00:00.001 - INFO - data from WebSocket: {'asks': [['0.55514', '562.9231', '4705448053']], 'bids': []}  - get_price_websocket_level2
09:00:00.001 - DEBUG - Data from socket: {'asks': [['0.55514', '562.9231', '4705448053']], 'bids': []} - get_price_websocket_level2
09:00:00.002 - INFO - Successfully retrieved XRP price: {'asks': [['0.55514', '562.9231', '4705448053']], 'bids': []} - main
12:15:00.002 - DEBUG - Received data: {'topic': '/market/level2:XRP-USDT', 'type': 'message', 'subject': 'trade.l2update', 'data': {'changes': {'asks': [['0.5532', '0', '4705933054']], 'bids': []}, 'sequenceEnd': 4705933054, 'sequenceStart': 4705933054, 'symbol': 'XRP-USDT', 'time': 1731153363283}} - get_price_websocket_level2
12:15:00.003 - INFO - data from WebSocket: {'asks': [['0.5532', '0', '4705933054']], 'bids': []}  - get_price_websocket_level2
12:15:00.004 - DEBUG - Data from socket: {'asks': [['0.5532', '0', '4705933054']], 'bids': []} - get_price_websocket_level2
12:15:00.005 - INFO - Successfully retrieved XRP price: {'asks': [['0.5532', '0', '4705933054']], 'bids': []} - main
12:30:00.002 - DEBUG - Received data: {'topic': '/market/level2:XRP-USDT', 'type': 'message', 'subject': 'trade.l2update', 'data': {'changes': {'asks': [], 'bids': [['0.55146', '6797.0435', '4705988485']]}, 'sequenceEnd': 4705988485, 'sequenceStart': 4705988485, 'symbol': 'XRP-USDT', 'time': 1731154563542}} - get_price_websocket_level2
12:30:00.003 - INFO - data from WebSocket: {'asks': [], 'bids': [['0.55146', '6797.0435', '4705988485']]}  - get_price_websocket_level2
12:30:00.003 - DEBUG - Data from socket: {'asks': [], 'bids': [['0.55146', '6797.0435', '4705988485']]} - get_price_websocket_level2
12:30:00.003 - INFO - Successfully retrieved XRP price: {'asks': [], 'bids': [['0.55146', '6797.0435', '4705988485']]} - main
12:45:00.012 - DEBUG - Received data: {'topic': '/market/level2:XRP-USDT', 'type': 'message', 'subject': 'trade.l2update', 'data': {'changes': {'asks': [], 'bids': [['0.54936', '0', '4706041025']]}, 'sequenceEnd': 4706041025, 'sequenceStart': 4706041025, 'symbol': 'XRP-USDT', 'time': 1731155463005}} - get_price_websocket_level2
12:45:00.012 - INFO - data from WebSocket: {'asks': [], 'bids': [['0.54936', '0', '4706041025']]}  - get_price_websocket_level2
12:45:00.012 - DEBUG - Data from socket: {'asks': [], 'bids': [['0.54936', '0', '4706041025']]} - get_price_websocket_level2
12:45:00.012 - INFO - Successfully retrieved XRP price: {'asks': [], 'bids': [['0.54936', '0', '4706041025']]} - main
13:00:00.006 - DEBUG - Received data: {'topic': '/market/level2:XRP-USDT', 'type': 'message', 'subject': 'trade.l2update', 'data': {'changes': {'asks': [['0.55084', '2915.3217', '4706084853']], 'bids': []}, 'sequenceEnd': 4706084853, 'sequenceStart': 4706084853, 'symbol': 'XRP-USDT', 'time': 1731156362945}} - get_price_websocket_level2
13:00:00.007 - INFO - data from WebSocket: {'asks': [['0.55084', '2915.3217', '4706084853']], 'bids': []}  - get_price_websocket_level2
13:00:00.010 - DEBUG - Data from socket: {'asks': [['0.55084', '2915.3217', '4706084853']], 'bids': []} - get_price_websocket_level2
13:00:00.010 - INFO - Successfully retrieved XRP price: {'asks': [['0.55084', '2915.3217', '4706084853']], 'bids': []} - main
13:15:00.002 - DEBUG - Received data: {'topic': '/market/level2:XRP-USDT', 'type': 'message', 'subject': 'trade.l2update', 'data': {'changes': {'asks': [['0.7149', '2.7472', '4706131824']], 'bids': []}, 'sequenceEnd': 4706131824, 'sequenceStart': 4706131824, 'symbol': 'XRP-USDT', 'time': 1731157263330}} - get_price_websocket_level2
13:15:00.003 - INFO - data from WebSocket: {'asks': [['0.7149', '2.7472', '4706131824']], 'bids': []}  - get_price_websocket_level2
13:15:00.003 - DEBUG - Data from socket: {'asks': [['0.7149', '2.7472', '4706131824']], 'bids': []} - get_price_websocket_level2
13:15:00.004 - INFO - Successfully retrieved XRP price: {'asks': [['0.7149', '2.7472', '4706131824']], 'bids': []} - main
13:30:00.003 - DEBUG - Received data: {'topic': '/market/level2:XRP-USDT', 'type': 'message', 'subject': 'trade.l2update', 'data': {'changes': {'asks': [], 'bids': [['0.49781', '168.924', '4706170378']]}, 'sequenceEnd': 4706170378, 'sequenceStart': 4706170378, 'symbol': 'XRP-USDT', 'time': 1731158163378}} - get_price_websocket_level2
13:30:00.003 - INFO - data from WebSocket: {'asks': [], 'bids': [['0.49781', '168.924', '4706170378']]}  - get_price_websocket_level2
13:30:00.003 - DEBUG - Data from socket: {'asks': [], 'bids': [['0.49781', '168.924', '4706170378']]} - get_price_websocket_level2
13:30:00.004 - INFO - Successfully retrieved XRP price: {'asks': [], 'bids': [['0.49781', '168.924', '4706170378']]} - main
13:45:00.000 - DEBUG - Received data: {'topic': '/market/level2:XRP-USDT', 'type': 'message', 'subject': 'trade.l2update', 'data': {'changes': {'asks': [], 'bids': [['0.54647', '32.8177', '4706217717']]}, 'sequenceEnd': 4706217717, 'sequenceStart': 4706217717, 'symbol': 'XRP-USDT', 'time': 1731159062992}} - get_price_websocket_level2
13:45:00.003 - INFO - data from WebSocket: {'asks': [], 'bids': [['0.54647', '32.8177', '4706217717']]}  - get_price_websocket_level2
13:45:00.004 - DEBUG - Data from socket: {'asks': [], 'bids': [['0.54647', '32.8177', '4706217717']]} - get_price_websocket_level2
13:45:00.004 - INFO - Successfully retrieved XRP price: {'asks': [], 'bids': [['0.54647', '32.8177', '4706217717']]} - main
14:00:00.001 - DEBUG - Received data: {'topic': '/market/level2:XRP-USDT', 'type': 'message', 'subject': 'trade.l2update', 'data': {'changes': {'asks': [['0.54904', '0', '4706260837']], 'bids': []}, 'sequenceEnd': 4706260837, 'sequenceStart': 4706260837, 'symbol': 'XRP-USDT', 'time': 1731159962993}} - get_price_websocket_level2
14:00:00.001 - INFO - data from WebSocket: {'asks': [['0.54904', '0', '4706260837']], 'bids': []}  - get_price_websocket_level2
14:00:00.001 - DEBUG - Data from socket: {'asks': [['0.54904', '0', '4706260837']], 'bids': []} - get_price_websocket_level2
14:00:00.001 - INFO - Successfully retrieved XRP price: {'asks': [['0.54904', '0', '4706260837']], 'bids': []} - main
10:00:00.053 - DEBUG - Received data: {'topic': '/market/level2:LUCE-USDT', 'type': 'message', 'subject': 'trade.l2update', 'data': {'changes': {'asks': [['0.109', '30700', '8']], 'bids': []}, 'sequenceEnd': 8, 'sequenceStart': 8, 'symbol': 'LUCE-USDT', 'time': 1731319200015}} - get_price_websocket_level2
10:00:00.053 - INFO - data from WebSocket: {'asks': [['0.109', '30700', '8']], 'bids': []}  - get_price_websocket_level2
10:00:00.053 - DEBUG - Data from socket: {'asks': [['0.109', '30700', '8']], 'bids': []} - get_price_websocket_level2
10:00:00.053 - INFO - Successfully retrieved LUCE price: {'asks': [['0.109', '30700', '8']], 'bids': []} - main
12:00:00.168 - DEBUG - Received data: {'topic': '/market/level2:PNUT-USDT', 'type': 'message', 'subject': 'trade.l2update', 'data': {'changes': {'asks': [['0.51', '1174', '1']], 'bids': []}, 'sequenceEnd': 1, 'sequenceStart': 1, 'symbol': 'PNUT-USDT', 'time': 1731326400130}} - get_price_websocket_level2
12:00:00.168 - INFO - data from WebSocket: {'asks': [['0.51', '1174', '1']], 'bids': []}  - get_price_websocket_level2
12:00:00.168 - DEBUG - Data from socket: {'asks': [['0.51', '1174', '1']], 'bids': []} - get_price_websocket_level2
12:00:00.168 - INFO - Successfully retrieved PNUT price: {'asks': [['0.51', '1174', '1']], 'bids': []} - main
08:15:00.008 - DEBUG - Received data: {'topic': '/market/level2:XRP-USDT', 'type': 'message', 'subject': 'trade.l2update', 'data': {'changes': {'asks': [['0.6649', '36.0167', '4744036876']], 'bids': []}, 'sequenceEnd': 4744036876, 'sequenceStart': 4744036876, 'symbol': 'XRP-USDT', 'time': 1731398463324}} - get_price_websocket_level2
08:15:00.008 - INFO - data from WebSocket: {'asks': [['0.6649', '36.0167', '4744036876']], 'bids': []}  - get_price_websocket_level2
08:15:00.008 - DEBUG - Data from socket: {'asks': [['0.6649', '36.0167', '4744036876']], 'bids': []} - get_price_websocket_level2
08:15:00.009 - INFO - Successfully retrieved XRP price: {'asks': [['0.6649', '36.0167', '4744036876']], 'bids': []} - main
08:30:00.008 - DEBUG - Received data: {'topic': '/market/level2:XRP-USDT', 'type': 'message', 'subject': 'trade.l2update', 'data': {'changes': {'asks': [['0.62044', '114.3035', '4744224897']], 'bids': []}, 'sequenceEnd': 4744224897, 'sequenceStart': 4744224897, 'symbol': 'XRP-USDT', 'time': 1731399363162}} - get_price_websocket_level2
08:30:00.009 - INFO - data from WebSocket: {'asks': [['0.62044', '114.3035', '4744224897']], 'bids': []}  - get_price_websocket_level2
08:30:00.009 - DEBUG - Data from socket: {'asks': [['0.62044', '114.3035', '4744224897']], 'bids': []} - get_price_websocket_level2
08:30:00.009 - INFO - Successfully retrieved XRP price: {'asks': [['0.62044', '114.3035', '4744224897']], 'bids': []} - main
09:00:00.088 - DEBUG - Received data: {'topic': '/market/level2:PEAQ-USDT', 'type': 'message', 'subject': 'trade.l2update', 'data': {'changes': {'asks': [], 'bids': [['0.085', '504180', '222']]}, 'sequenceEnd': 222, 'sequenceStart': 222, 'symbol': 'PEAQ-USDT', 'time': 1731402000044}} - get_price_websocket_level2
09:00:00.089 - INFO - data from WebSocket: {'asks': [], 'bids': [['0.085', '504180', '222']]}  - get_price_websocket_level2
09:00:00.089 - DEBUG - Data from socket: {'asks': [], 'bids': [['0.085', '504180', '222']]} - get_price_websocket_level2
09:00:00.090 - INFO - Successfully retrieved PEAQ price: {'asks': [], 'bids': [['0.085', '504180', '222']]} - main
12:00:00.059 - DEBUG - Received data: {'topic': '/market/level2:PGC-USDT', 'type': 'message', 'subject': 'trade.l2update', 'data': {'changes': {'asks': [], 'bids': [['0.01', '103963', '41']]}, 'sequenceEnd': 41, 'sequenceStart': 41, 'symbol': 'PGC-USDT', 'time': 1731412800009}} - get_price_websocket_level2
12:00:00.059 - INFO - data from WebSocket: {'asks': [], 'bids': [['0.01', '103963', '41']]}  - get_price_websocket_level2
12:00:00.059 - DEBUG - Data from socket: {'asks': [], 'bids': [['0.01', '103963', '41']]} - get_price_websocket_level2
12:00:00.059 - INFO - Successfully retrieved PGC price: {'asks': [], 'bids': [['0.01', '103963', '41']]} - main
12:00:00.058 - INFO - data from WebSocket: {'asks': [['0.04976', '20096', '48']], 'bids': []}  - get_price_websocket_level2
12:00:00.058 - INFO - Successfully retrieved NOOB price: {'asks': [['0.04976', '20096', '48']], 'bids': []} - main
09:30:00.008 - INFO - data from WebSocket: {'asks': [['0.70806', '2761.7', '4806017857']], 'bids': []}  - get_price_websocket_level2
09:30:00.009 - INFO - Successfully retrieved XRP price: {'asks': [['0.70806', '2761.7', '4806017857']], 'bids': []} - main
10:30:00.002 - INFO - data from WebSocket: {'asks': [], 'bids': [['0.71169', '1587.6473', '4806721375']]}  - get_price_websocket_level2
10:30:00.003 - INFO - Successfully retrieved XRP price: {'asks': [], 'bids': [['0.71169', '1587.6473', '4806721375']]} - main
11:00:00.095 - INFO - data from WebSocket: {'asks': [['0.09', '0', '100']], 'bids': []}  - get_price_websocket_level2
11:00:00.095 - INFO - Successfully retrieved NS price: {'asks': [['0.09', '0', '100']], 'bids': []} - main
19:45:00.002 - INFO - data from WebSocket: {'asks': [], 'bids': [['0.77945', '640.6955', '4818838496']]}  - get_price_websocket_level2
19:45:00.009 - INFO - Successfully retrieved XRP price: {'asks': [], 'bids': [['0.77945', '640.6955', '4818838496']]} - main
20:00:00.004 - INFO - data from WebSocket: {'asks': [['0.79476', '0', '4819218507']], 'bids': []}  - get_price_websocket_level2
20:00:00.004 - INFO - Successfully retrieved XRP price: {'asks': [['0.79476', '0', '4819218507']], 'bids': []} - main
20:32:00.002 - INFO - data from WebSocket: {'asks': [], 'bids': [['0.77623', '1.5598', '4820194477']]}  - get_price_websocket_level2
20:32:00.005 - INFO - Successfully retrieved XRP price: {'asks': [], 'bids': [['0.77623', '1.5598', '4820194477']]} - main
20:47:00.002 - INFO - data from WebSocket: {'asks': [], 'bids': [['0.76612', '1814.3484', '4820487999']]}  - get_price_websocket_level2
20:47:00.004 - INFO - Successfully retrieved XRP price: {'asks': [], 'bids': [['0.76612', '1814.3484', '4820487999']]} - main
21:47:00.003 - INFO - data from WebSocket: {'asks': [['0.80676', '1239.4718', '4821422098']], 'bids': []}  - get_price_websocket_level2
21:47:00.004 - INFO - Successfully retrieved XRP price: {'asks': [['0.80676', '1239.4718', '4821422098']], 'bids': []} - main
10:00:00.159 - INFO - data from WebSocket: {'asks': [['0.6996', '355.84', '268']], 'bids': []}  - get_price_websocket_level2
10:00:00.159 - INFO - Successfully retrieved MICHI price: {'asks': [['0.6996', '355.84', '268']], 'bids': []} - main
